Traceback (most recent call last):
  File "/usr/local/lib/python3.2/dist-packages/pymysql/connections.py", line 661, in _connect
    sock.connect((self.host, self.port))
socket.error: [Errno 111] Connection refused

During handling of the above exception, another exception occurred:

Traceback (most recent call last):
  File "/home/pi/Desktop/RPi/tcpClient_python3.py", line 6, in <module>
    from backfill import database_backup
  File "/home/pi/Desktop/RPi/backfill.py", line 4, in <module>
    conn = pymysql.connect(host="localhost",port=3306, user="root", passwd="aaggss", db="dredger")
  File "/usr/local/lib/python3.2/dist-packages/pymysql/__init__.py", line 93, in Connect
    return Connection(*args, **kwargs)
  File "/usr/local/lib/python3.2/dist-packages/pymysql/connections.py", line 513, in __init__
    self._connect()
  File "/usr/local/lib/python3.2/dist-packages/pymysql/connections.py", line 669, in _connect
    raise OperationalError(2003, "Can't connect to MySQL server on %r (%d)" % (self.host, e.args[0]))
pymysql.err.OperationalError: (2003, "Can't connect to MySQL server on 'localhost' (111)")
